Workbook
Name _______________________SET87: '[1]000000'!$C$5:$P$50
Name ______________________SET87: '[2]000000'!$C$5:$P$50
Name _____________________SET87: '[2]000000'!$C$5:$P$50
Name ____________________SET87: '[2]000000'!$C$5:$P$50
Name ___________________\a: #REF!
Name ___________________SET87: '[2]000000'!$C$5:$P$50
Name __________________SET87: '[2]000000'!$C$5:$P$50
Name _________________\a: #REF!
Name _________________SET87: '[2]000000'!$C$5:$P$50
Name ________________\a: #REF!
Name ________________SET87: '[2]000000'!$C$5:$P$50
Name _______________\a: #REF!
Name _______________DAF1: [3]Sheet3!$II$7944
Name _______________SET87: '[2]000000'!$C$5:$P$50
Name ______________\a: #REF!
Name ______________DAF1: [3]Sheet3!$II$7944
Name ______________SET87: '[2]000000'!$C$5:$P$50
Name _____________DAF1: [3]Sheet3!$II$7944
Name _____________SET87: '[2]000000'!$C$5:$P$50
Name ____________\a: #REF!
Name ____________DAF1: [3]Sheet3!$II$7944
Name ____________SET87: '[4]000000'!$C$5:$P$50
Name ___________\a: #REF!
Name ___________DAF1: [3]Sheet3!$II$7944
Name ___________SET87: '[4]000000'!$C$5:$P$50
Name __________DAF1: [3]Sheet3!$II$7944
Name __________SET87: '[4]000000'!$C$5:$P$50
Name _________\a: #REF!
Name _________DAF1: [3]Sheet3!$II$7944
Name _________SET87: '[4]000000'!$C$5:$P$50
Name ________\a: #REF!
Name ________BAT48100: '[5]HARGA SATUAN'!$B$13
Name ________DAF1: [3]Sheet3!$II$7944
Name ________la150: '[5]HARGA SATUAN'!$B$25
Name ________pmt7040: '[5]HARGA SATUAN'!$B$8
Name ________SET87: '[4]000000'!$C$5:$P$50
Name _______\a: #REF!
Name _______BAT48100: '[5]HARGA SATUAN'!$B$13
Name _______DAF1: [3]Sheet3!$II$7944
Name _______la150: '[5]HARGA SATUAN'!$B$25
Name _______pmt7040: '[5]HARGA SATUAN'!$B$8
Name _______SET87: '[4]000000'!$C$5:$P$50
Name ______\a: #REF!
Name ______BAT48100: '[5]HARGA SATUAN'!$B$13
Name ______DAF1: [3]Sheet3!$II$7944
Name ______la150: '[5]HARGA SATUAN'!$B$25
Name ______pmt7040: '[5]HARGA SATUAN'!$B$8
Name ______SET87: '[4]000000'!$C$5:$P$50
Name _____\a: #REF!
Name _____BAT48100: '[5]HARGA SATUAN'!$B$13
Name _____DAF1: [7]Sheet3!$II$7944
Name _____la150: '[5]HARGA SATUAN'!$B$25
Name _____pmt7040: '[5]HARGA SATUAN'!$B$8
Name _____SET87: '[4]000000'!$C$5:$P$50
Name _____TCU1: [8]Assumptions!$E$13
Name _____TCU2: [8]Assumptions!$F$13
Name ____\a: #REF!
Name ____BAT48100: '[5]HARGA SATUAN'!$B$13
Name ____DAF1: [3]Sheet3!$II$7944
Name ____la150: '[5]HARGA SATUAN'!$B$25

Sheet  TRAFO 80% no print  
B2: BEBAN TRAFO GARDU INDUK DISTRIBUSI JABAR & BANTEN
A7: LAMPIRAN XIII.1
A8: BEBAN TRAFO GARDU INDUK ≥ 80% UNIT INDUK DISTRIBUSI JAWA BARAT
A9: APRIL 2022
A11: N0 | B11: UP3 | C11: GI | D11: TRF | E11: DAYA | F11: TGN | G11: I-NOM | H11: April | L11: KETERANGAN
H12: Siang | J12: Malam
F13: (kV) | H13: A | I13: % | J13: A | K13: % | Z13: A | AA13: % | AB13: TEG | AC13: TANGGAL | AD13: SIANG/MALAM
A14: 1 | B14: BEKASI | C14: BKASI | D14: 1 | E14: 60 | F14: 150/20 | G14: 1732 | H14: 1297.4959 | I14: 74.913158 | J14: 1413.2721 | K14: 81.597694 | L14: Kawaasan industri & umum Bekasi | O14: =IF(I14>=80,"B","K") -> K | P14: =IF(K14>=80,"B","K") -> B | R14: =(H14/G14)*100 -> 74.913158 | S14: =J14/G14*100 -> 81.597694 | U14: =IF(R14=I14,"BETUL","salah") -> BETUL | V14: =IF(K14=S14,"BETUL","SALAH") -> BETUL | W14: =IF(I14>80,"CEK KEMBALI","OKE") -> OKE | X14: =IF(K14>80,"CEK KEMBALI","OKE") -> CEK KEMBALI | Z14: =MAX(H14,J14) -> 1413.2721 | AA14: =MAX(I14,K14) -> 81.597694 | AB14: =IF(Z14=H14,#REF!,#REF!) -> #REF! | AC14: =IF(Z14=H14,#REF!,#REF!) -> #REF! | AD14: =IF(Z14=H14,"Siang","Malam") -> Malam
A15: 2 | B15: CIKARANG | C15: CBATU | D15: 2 | E15: 60 | F15: 150/20 | G15: 1732 | H15: 1460.3447 | I15: 84.315513 | J15: 1466.1169 | K15: 84.64878 | L15: Wilayah Umum Cibatu,Sukamanah, Cicau | O15: =IF(I15>=80,"B","K") -> B | P15: =IF(K15>=80,"B","K") -> B | R15: =(H15/G15)*100 -> 84.315513 | S15: =J15/G15*100 -> 84.64878 | U15: =IF(R15=I15,"BETUL","salah") -> BETUL | V15: =IF(K15=S15,"BETUL","SALAH") -> BETUL | W15: =IF(I15>80,"CEK KEMBALI","OKE") -> CEK KEMBALI | X15: =IF(K15>80,"CEK KEMBALI","OKE") -> CEK KEMBALI | Z15: =MAX(H15,J15) -> 1466.1169 | AA15: =MAX(I15,K15) -> 84.64878 | AB15: =IF(Z15=H15,#REF!,#REF!) -> #REF! | AC15: =IF(Z15=H15,#REF!,#REF!) -> #REF! | AD15: =IF(Z15=H15,"Siang","Malam") -> Malam
A16: 3 | B16: CIKARANG | C16: GDMKR | D16: 2 | E16: 60 | F16: 150/20 | G16: 1732 | H16: 1564.3778 | I16: 90.322047 | J16: 1429.3363 | K16: 82.525188 | L16: Kawasan industri dan Cikarang Bekasi | O16: =IF(I16>=80,"B","K") -> B | P16: =IF(K16>=80,"B","K") -> B | R16: =(H16/G16)*100 -> 90.322047 | S16: =J16/G16*100 -> 82.525188 | U16: =IF(R16=I16,"BETUL","salah") -> BETUL | V16: =IF(K16=S16,"BETUL","SALAH") -> BETUL | W16: =IF(I16>80,"CEK KEMBALI","OKE") -> CEK KEMBALI | X16: =IF(K16>80,"CEK KEMBALI","OKE") -> CEK KEMBALI | Z16: =MAX(H16,J16) -> 1564.3778 | AA16: =MAX(I16,K16) -> 90.322047 | AB16: =IF(Z16=H16,#REF!,#REF!) -> #REF! | AC16: =IF(Z16=H16,#REF!,#REF!) -> #REF! | AD16: =IF(Z16=H16,"Siang","Malam") -> Siang
A17: 4 | B17: CIKARANG | C17: GDMKR | D17: 3 | E17: 60 | F17: 150/20 | G17: 1732 | H17: 1633.315 | I17: 94.302251 | J17: 1390.0004 | K17: 80.254067 | L17: Kawasan industri dan Cikarang Bekasi | O17: =IF(I17>=80,"B","K") -> B | P17: =IF(K17>=80,"B","K") -> B | R17: =(H17/G17)*100 -> 94.302251 | S17: =J17/G17*100 -> 80.254067 | U17: =IF(R17=I17,"BETUL","salah") -> BETUL | V17: =IF(K17=S17,"BETUL","SALAH") -> BETUL | W17: =IF(I17>80,"CEK KEMBALI","OKE") -> CEK KEMBALI | X17: =IF(K17>80,"CEK KEMBALI","OKE") -> CEK KEMBALI | Z17: =MAX(H17,J17) -> 1633.315 | AA17: =MAX(I17,K17) -> 94.302251 | AB17: =IF(Z17=H17,#REF!,#REF!) -> #REF! | AC17: =IF(Z17=H17,#REF!,#REF!) -> #REF! | AD17: =IF(Z17=H17,"Siang","Malam") -> Siang
A18: 5 | B18: CIKARANG | C18: JBBKA | D18: 2 | E18: 60 | F18: 150/20 | G18: 1732 | H18: 1404.3032 | I18: 81.07986 | J18: 1203.5715 | K18: 69.490271 | L18: Kawasan industri Jababeka Bekasi | O18: =IF(I18>=80,"B","K") -> B | P18: =IF(K18>=80,"B","K") -> K | R18: =(H18/G18)*100 -> 81.07986 | S18: =J18/G18*100 -> 69.490271 | U18: =IF(R18=I18,"BETUL","salah") -> BETUL | V18: =IF(K18=S18,"BETUL","SALAH") -> BETUL | W18: =IF(I18>80,"CEK KEMBALI","OKE") -> CEK KEMBALI | X18: =IF(K18>80,"CEK KEMBALI","OKE") -> OKE | Z18: =MAX(H18,J18) -> 1404.3032 | AA18: =MAX(I18,K18) -> 81.07986 | AB18: =IF(Z18=H18,#REF!,#REF!) -> #REF! | AC18: =IF(Z18=H18,#REF!,#REF!) -> #REF! | AD18: =IF(Z18=H18,"Siang","Malam") -> Siang
A19: 6 | B19: CIKARANG | C19: JBBKA | D19: 3 | E19: 60 | F19: 150/20 | G19: 1732 | H19: 1443.179 | I19: 83.324422 | J19: 317.17751 | K19: 18.312789 | L19: Kawasan industri Jababeka Bekasi | O19: =IF(I19>=80,"B","K") -> B | P19: =IF(K19>=80,"B","K") -> K | R19: =(H19/G19)*100 -> 83.324422 | S19: =J19/G19*100 -> 18.312789 | U19: =IF(R19=I19,"BETUL","salah") -> BETUL | V19: =IF(K19=S19,"BETUL","SALAH") -> BETUL | W19: =IF(I19>80,"CEK KEMBALI","OKE") -> CEK KEMBALI | X19: =IF(K19>80,"CEK KEMBALI","OKE") -> OKE | Z19: =MAX(H19,J19) -> 1443.179 | AA19: =MAX(I19,K19) -> 83.324422 | AB19: =IF(Z19=H19,#REF!,#REF!) -> #REF! | AC19: =IF(Z19=H19,#REF!,#REF!) -> #REF! | AD19: =IF(Z19=H19,"Siang","Malam") -> Siang
A20: 7 | B20: CIKARANG | C20: JBBKA | D20: 4 | E20: 60 | F20: 150/20 | G20: 1732 | H20: 1436.2874 | I20: 82.926522 | J20: 1314.3207 | K20: 75.884568 | L20: Kawasan industri Jababeka Bekasi | O20: =IF(I20>=80,"B","K") -> B | P20: =IF(K20>=80,"B","K") -> K | R20: =(H20/G20)*100 -> 82.926522 | S20: =J20/G20*100 -> 75.884568 | U20: =IF(R20=I20,"BETUL","salah") -> BETUL | V20: =IF(K20=S20,"BETUL","SALAH") -> BETUL | W20: =IF(I20>80,"CEK KEMBALI","OKE") -> CEK KEMBALI | X20: =IF(K20>80,"CEK KEMBALI","OKE") -> OKE | Z20: =MAX(H20,J20) -> 1436.2874 | AA20: =MAX(I20,K20) -> 82.926522 | AB20: =IF(Z20=H20,#REF!,#REF!) -> #REF! | AC20: =IF(Z20=H20,#REF!,#REF!) -> #REF! | AD20: =IF(Z20=H20,"Siang","Malam") -> Siang
A21: 8 | B21: BEKASI | C21: PCBRU | D21: 1 | E21: 60 | F21: 150/20 | G21: 1732 | H21: 1568.1989 | I21: 90.542661 | J21: 1440.3797 | K21: 83.162799 | L21: Wilayah Kalimalang, Margahayu dan Bulak Kapal | O21: =IF(I21>=80,"B","K") -> B | P21: =IF(K21>=80,"B","K") -> B | R21: =(H21/G21)*100 -> 90.542661 | S21: =J21/G21*100 -> 83.162799 | U21: =IF(R21=I21,"BETUL","salah") -> BETUL | V21: =IF(K21=S21,"BETUL","SALAH") -> BETUL | W21: =IF(I21>80,"CEK KEMBALI","OKE") -> CEK KEMBALI | X21: =IF(K21>80,"CEK KEMBALI","OKE") -> CEK KEMBALI | Z21: =MAX(H21,J21) -> 1568.1989 | AA21: =MAX(I21,K21) -> 90.542661 | AB21: =IF(Z21=H21,#REF!,#REF!) -> #REF! | AC21: =IF(Z21=H21,#REF!,#REF!) -> #REF! | AD21: =IF(Z21=H21,"Siang","Malam") -> Siang
A22: 9 | B22: BEKASI | C22: PCBRU | D22: 3 | E22: 60 | F22: 150/20 | G22: 1732 | H22: 1443.6778 | I22: 83.35322 | J22: 1442.9189 | K22: 83.309408 | L22: Wilayah Bekasi kota, Kejaksaan, Polres | O22: =IF(I22>=80,"B","K") -> B | P22: =IF(K22>=80,"B","K") -> B | R22: =(H22/G22)*100 -> 83.35322 | S22: =J22/G22*100 -> 83.309408 | U22: =IF(R22=I22,"BETUL","salah") -> BETUL | V22: =IF(K22=S22,"BETUL","SALAH") -> BETUL | W22: =IF(I22>80,"CEK KEMBALI","OKE") -> CEK KEMBALI | X22: =IF(K22>80,"CEK KEMBALI","OKE") -> CEK KEMBALI | Z22: =MAX(H22,J22) -> 1443.6778 | AA22: =MAX(I22,K22) -> 83.35322 | AB22: =IF(Z22=H22,#REF!,#REF!) -> #REF! | AC22: =IF(Z22=H22,#REF!,#REF!) -> #REF! | AD22: =IF(Z22=H22,"Siang","Malam") -> Siang
A23: 10 | B23: BEKASI | C23: TMBUN | D23: 2 | E23: 60 | F23: 150/20 | G23: 1732 | H23: 1447.7187 | I23: 83.586528 | J23: 1379.9654 | K23: 79.674677 | L23: Wilayah Kota Legenda dan Bekasi Timur | O23: =IF(I23>=80,"B","K") -> B | P23: =IF(K23>=80,"B","K") -> K | R23: =(H23/G23)*100 -> 83.586528 | S23: =J23/G23*100 -> 79.674677 | U23: =IF(R23=I23,"BETUL","salah") -> BETUL | V23: =IF(K23=S23,"BETUL","SALAH") -> BETUL | W23: =IF(I23>80,"CEK KEMBALI","OKE") -> CEK KEMBALI | X23: =IF(K23>80,"CEK KEMBALI","OKE") -> OKE | Z23: =MAX(H23,J23) -> 1447.7187 | AA23: =MAX(I23,K23) -> 83.586528 | AB23: =IF(Z23=H23,#REF!,#REF!) -> #REF! | AC23: =IF(Z23=H23,#REF!,#REF!) -> #REF! | AD23: =IF(Z23=H23,"Siang","Malam") -> Siang
A24: 11 | B24: BEKASI | C24: TMBUN | D24: 3 | E24: 60 | F24: 150/20 | G24: 1732 | H24: 1405.2771 | I24: 81.136089 | J24: 1381.557 | K24: 79.766573 | L24: Wilayah Kota Legenda dan Bekasi Timur | O24: =IF(I24>=80,"B","K") -> B | P24: =IF(K24>=80,"B","K") -> K | R24: =(H24/G24)*100 -> 81.136089 | S24: =J24/G24*100 -> 79.766573 | U24: =IF(R24=I24,"BETUL","salah") -> BETUL | V24: =IF(K24=S24,"BETUL","SALAH") -> BETUL | W24: =IF(I24>80,"CEK KEMBALI","OKE") -> CEK KEMBALI | X24: =IF(K24>80,"CEK KEMBALI","OKE") -> OKE | Z24: =MAX(H24,J24) -> 1405.2771 | AA24: =MAX(I24,K24) -> 81.136089 | AB24: =IF(Z24=H24,#REF!,#REF!) -> #REF! | AC24: =IF(Z24=H24,#REF!,#REF!) -> #REF! | AD24: =IF(Z24=H24,"Siang","Malam") -> Siang
A25: 12 | B25: BEKASI | C25: TMBUN | D25: 5 | E25: 60 | F25: 150/20 | G25: 1732 | H25: 1408.4894 | I25: 81.32156 | J25: 1414.1236 | K25: 81.64686 | L25: Wilayah Kota Legenda dan Bekasi Timur | O25: =IF(I25>=80,"B","K") -> B | P25: =IF(K25>=80,"B","K") -> B | R25: =(H25/G25)*100 -> 81.32156 | S25: =J25/G25*100 -> 81.64686 | U25: =IF(R25=I25,"BETUL","salah") -> BETUL | V25: =IF(K25=S25,"BETUL","SALAH") -> BETUL | W25: =IF(I25>80,"CEK KEMBALI","OKE") -> CEK KEMBALI | X25: =IF(K25>80,"CEK KEMBALI","OKE") -> CEK KEMBALI | Z25: =MAX(H25,J25) -> 1414.1236 | AA25: =MAX(I25,K25) -> 81.64686 | AB25: =IF(Z25=H25,#REF!,#REF!) -> #REF! | AC25: =IF(Z25=H25,#REF!,#REF!) -> #REF! | AD25: =IF(Z25=H25,"Siang","Malam") -> Malam
... A52: 39 | B52: SUMEDANG | C52: PRKAN | D52: 3 | E52: 10 | F52: 70/20 | G52: 288 | H52: 241.75886 | I52: 83.944047 | J52: 237.1976 | K52: 82.360278 | L52: Parakan kondang, Cijeungjing | O52: =IF(I52>=80,"B","K") -> B | P52: =IF(K52>=80,"B","K") -> B | R52: =(H52/G52)*100 -> 83.944047 | S52: =J52/G52*100 -> 82.360278 | U52: =IF(R52=I52,"BETUL","salah") -> BETUL | V52: =IF(K52=S52,"BETUL","SALAH") -> BETUL | W52: =IF(I52>80,"CEK KEMBALI","OKE") -> CEK KEMBALI | X52: =IF(K52>80,"CEK KEMBALI","OKE") -> CEK KEMBALI | Z52: =MAX(H52,J52) -> 241.75886 | AA52: =MAX(I52,K52) -> 83.944047 | AB52: =IF(Z52=H52,#REF!,#REF!) -> #REF! | AC52: =IF(Z52=H52,#REF!,#REF!) -> #REF! | AD52: =IF(Z52=H52,"Siang","Malam") -> Siang
A53: 40 | B53: SUMEDANG | C53: NUBRG | D53: 3 | E53: 60 | F53: 150/20 | G53: 1732 | H53: 1590.301 | I53: 91.818764 | J53: 670.04476 | K53: 38.686187 | O53: =IF(I53>=80,"B","K") -> B | P53: =IF(K53>=80,"B","K") -> K | R53: =(H53/G53)*100 -> 91.818764 | S53: =J53/G53*100 -> 38.686187 | U53: =IF(R53=I53,"BETUL","salah") -> BETUL | V53: =IF(K53=S53,"BETUL","SALAH") -> BETUL | W53: =IF(I53>80,"CEK KEMBALI","OKE") -> CEK KEMBALI | X53: =IF(K53>80,"CEK KEMBALI","OKE") -> OKE | Z53: =MAX(H53,J53) -> 1590.301 | AA53: =MAX(I53,K53) -> 91.818764 | AB53: =IF(Z53=H53,#REF!,#REF!) -> #REF! | AC53: =IF(Z53=H53,#REF!,#REF!) -> #REF! | AD53: =IF(Z53=H53,"Siang","Malam") -> Siang
A54: 41 | B54: TASIKMALAYA | C54: MLBNG | D54: 2 | E54: 30 | F54: 70/20 | G54: 866 | H54: 755.49908 | I54: 87.240079 | J54: 825.70795 | K54: 95.347338 | L54: Wilayah Umum Malambong,Tasik, | O54: =IF(I54>=80,"B","K") -> B | P54: =IF(K54>=80,"B","K") -> B | R54: =(H54/G54)*100 -> 87.240079 | S54: =J54/G54*100 -> 95.347338 | U54: =IF(R54=I54,"BETUL","salah") -> BETUL | V54: =IF(K54=S54,"BETUL","SALAH") -> BETUL | W54: =IF(I54>80,"CEK KEMBALI","OKE") -> CEK KEMBALI | X54: =IF(K54>80,"CEK KEMBALI","OKE") -> CEK KEMBALI | Z54: =MAX(H54,J54) -> 825.70795 | AA54: =MAX(I54,K54) -> 95.347338 | AB54: =IF(Z54=H54,#REF!,#REF!) -> #REF! | AC54: =IF(Z54=H54,#REF!,#REF!) -> #REF! | AD54: =IF(Z54=H54,"Siang","Malam") -> Malam
A55: 42 | B55: TASIKMALAYA | C55: MLBNG | D55: 3 | E55: 20 | F55: 70/20 | G55: 577 | H55: 461.38427 | I55: 79.962611 | J55: 522.75462 | K55: 90.598721 | L55: Wilayah Umum Malambong, Tasik, | O55: =IF(I55>=80,"B","K") -> K | P55: =IF(K55>=80,"B","K") -> B | R55: =(H55/G55)*100 -> 79.962611 | S55: =J55/G55*100 -> 90.598721 | U55: =IF(R55=I55,"BETUL","salah") -> BETUL | V55: =IF(K55=S55,"BETUL","SALAH") -> BETUL | W55: =IF(I55>80,"CEK KEMBALI","OKE") -> OKE | X55: =IF(K55>80,"CEK KEMBALI","OKE") -> CEK KEMBALI | Z55: =MAX(H55,J55) -> 522.75462 | AA55: =MAX(I55,K55) -> 90.598721 | AB55: =IF(Z55=H55,#REF!,#REF!) -> #REF! | AC55: =IF(Z55=H55,#REF!,#REF!) -> #REF! | AD55: =IF(Z55=H55,"Siang","Malam") -> Malam
A56: 43 | B56: TASIKMALAYA | C56: TSBRU | D56: 1 | E56: 30 | F56: 150/20 | G56: 866 | H56: 844.21712 | I56: 97.484656 | J56: 477.79404 | K56: 55.172522 | L56: Wilayah Umum Tasikmalaya | O56: =IF(I56>=80,"B","K") -> B | P56: =IF(K56>=80,"B","K") -> K | R56: =(H56/G56)*100 -> 97.484656 | S56: =J56/G56*100 -> 55.172522 | U56: =IF(R56=I56,"BETUL","salah") -> BETUL | V56: =IF(K56=S56,"BETUL","SALAH") -> BETUL | W56: =IF(I56>80,"CEK KEMBALI","OKE") -> CEK KEMBALI | X56: =IF(K56>80,"CEK KEMBALI","OKE") -> OKE | Z56: =MAX(H56,J56) -> 844.21712 | AA56: =MAX(I56,K56) -> 97.484656 | AB56: =IF(Z56=H56,#REF!,#REF!) -> #REF! | AC56: =IF(Z56=H56,#REF!,#REF!) -> #REF! | AD56: =IF(Z56=H56,"Siang","Malam") -> Siang

Sheet  TRAFO 30% no print
B2: BEBAN TRAFO GARDU INDUK DISTRIBUSI JABAR & BANTEN
A7: LAMPIRAN XIII.1
A8: BEBAN TRAFO GARDU INDUK < 30% DISTRIBUSI JAWA BARAT
A9: =' TRAFO 80% no print '!A9:K9 -> APRIL 2022
A11: N0 | B11: UP3 | C11: GI | D11: TRF | E11: DAYA | F11: TGN | G11: I-NOM | H11: April | L11: KETERANGAN
H12: Siang | J12: Malam
F13: (kV) | H13: A | I13: % | J13: A | K13: % | Z13: A | AA13: % | AB13: TEG | AC13: TANGGAL | AD13: SIANG/MALAM
A14: 1 | B14: BANDUNG | C14: BRAGA | D14: 2 | E14: 60 | F14: 150/20 | G14: 1732 | H14: 708.46141 | I14: 40.904238 | J14: 507.56437 | K14: 29.305102 | O14: =IF(I14>=80,"B","K") -> K | P14: K | R14: =(H14/G14)*100 -> 40.904238 | S14: =J14/G14*100 -> 29.305102 | U14: =IF(R14=I14,"BETUL","salah") -> BETUL | V14: =IF(K14=S14,"BETUL","SALAH") -> BETUL | W14: =IF(I14>80,"CEK KEMBALI","OKE") -> OKE | X14: =IF(K14>80,"CEK KEMBALI","OKE") -> OKE | Z14: =MIN(H14,J14) -> 507.56437 | AA14: =MIN(I14,K14) -> 29.305102 | AB14: =IF(Z14=H14,#REF!,#REF!) -> #REF! | AC14: =IF(Z14=H14,#REF!,#REF!) -> #REF! | AD14: =IF(Z14=H14,"Siang","Malam") -> Malam
A15: 2 | B15: BANDUNG | C15: DGPKR | D15: 1 | E15: 60 | F15: 150/20 | G15: 1732 | H15: 440.67873 | I15: 25.443345 | J15: 457.51828 | K15: 26.415605 | O15: =IF(I15>=80,"B","K") -> K | P15: K | R15: =(H15/G15)*100 -> 25.443345 | S15: =J15/G15*100 -> 26.415605 | U15: =IF(R15=I15,"BETUL","salah") -> BETUL | V15: =IF(K15=S15,"BETUL","SALAH") -> BETUL | W15: =IF(I15>80,"CEK KEMBALI","OKE") -> OKE | X15: =IF(K15>80,"CEK KEMBALI","OKE") -> OKE | Z15: =MIN(H15,J15) -> 440.67873 | AA15: =MIN(I15,K15) -> 25.443345 | AB15: =IF(Z15=H15,#REF!,#REF!) -> #REF! | AC15: =IF(Z15=H15,#REF!,#REF!) -> #REF! | AD15: =IF(Z15=H15,"Siang","Malam") -> Siang
A16: 3 | B16: BANDUNG | C16: UBRNG | D16: 6 | E16: 60 | F16: 150/20 | G16: 1732 | H16: 577.26754 | I16: 33.329534 | J16: 458.69184 | K16: 26.483363 | O16: =IF(I16>=80,"B","K") -> K | P16: K | R16: =(H16/G16)*100 -> 33.329534 | S16: =J16/G16*100 -> 26.483363 | U16: =IF(R16=I16,"BETUL","salah") -> BETUL | V16: =IF(K16=S16,"BETUL","SALAH") -> BETUL | W16: =IF(I16>80,"CEK KEMBALI","OKE") -> OKE | X16: =IF(K16>80,"CEK KEMBALI","OKE") -> OKE | Z16: =MIN(H16,J16) -> 458.69184 | AA16: =MIN(I16,K16) -> 26.483363 | AB16: =IF(Z16=H16,#REF!,#REF!) -> #REF! | AC16: =IF(Z16=H16,#REF!,#REF!) -> #REF! | AD16: =IF(Z16=H16,"Siang","Malam") -> Malam
A17: 4 | B17: BANDUNG | C17: UBRNG | D17: 7 | E17: 60 | F17: 150/20 | G17: 1732 | H17: 291.70409 | I17: 16.842038 | J17: 274.54292 | K17: 15.851208 | O17: =IF(I17>=80,"B","K") -> K | P17: K | R17: =(H17/G17)*100 -> 16.842038 | S17: =J17/G17*100 -> 15.851208 | U17: =IF(R17=I17,"BETUL","salah") -> BETUL | V17: =IF(K17=S17,"BETUL","SALAH") -> BETUL | W17: =IF(I17>80,"CEK KEMBALI","OKE") -> OKE | X17: =IF(K17>80,"CEK KEMBALI","OKE") -> OKE | Z17: =MIN(H17,J17) -> 274.54292 | AA17: =MIN(I17,K17) -> 15.851208 | AB17: =IF(Z17=H17,#REF!,#REF!) -> #REF! | AC17: =IF(Z17=H17,#REF!,#REF!) -> #REF! | AD17: =IF(Z17=H17,"Siang","Malam") -> Malam
A18: 5 | B18: BANDUNG | C18: GDBGE | D18: 1 | E18: 60 | F18: 150/20 | G18: 1732 | H18: 442.54146 | I18: 25.550893 | J18: 420.0743 | K18: 24.253712 | O18: =IF(I18>=80,"B","K") -> K | P18: K | R18: =(H18/G18)*100 -> 25.550893 | S18: =J18/G18*100 -> 24.253712 | U18: =IF(R18=I18,"BETUL","salah") -> BETUL | V18: =IF(K18=S18,"BETUL","SALAH") -> BETUL | W18: =IF(I18>80,"CEK KEMBALI","OKE") -> OKE | X18: =IF(K18>80,"CEK KEMBALI","OKE") -> OKE | Z18: =MIN(H18,J18) -> 420.0743 | AA18: =MIN(I18,K18) -> 24.253712 | AB18: =IF(Z18=H18,#REF!,#REF!) -> #REF! | AC18: =IF(Z18=H18,#REF!,#REF!) -> #REF! | AD18: =IF(Z18=H18,"Siang","Malam") -> Malam
A19: 6 | B19: BANDUNG | C19: GDBGE | D19: 2 | E19: 60 | F19: 150/20 | G19: 1732 | H19: 486.28374 | I19: 28.076429 | J19: 385.73621 | K19: 22.271144 | O19: =IF(I19>=80,"B","K") -> K | P19: K | R19: =(H19/G19)*100 -> 28.076429 | S19: =J19/G19*100 -> 22.271144 | U19: =IF(R19=I19,"BETUL","salah") -> BETUL | V19: =IF(K19=S19,"BETUL","SALAH") -> BETUL | W19: =IF(I19>80,"CEK KEMBALI","OKE") -> OKE | X19: =IF(K19>80,"CEK KEMBALI","OKE") -> OKE | Z19: =MIN(H19,J19) -> 385.73621 | AA19: =MIN(I19,K19) -> 22.271144 | AB19: =IF(Z19=H19,#REF!,#REF!) -> #REF! | AC19: =IF(Z19=H19,#REF!,#REF!) -> #REF! | AD19: =IF(Z19=H19,"Siang","Malam") -> Malam
A20: 7 | B20: CIKARANG | C20: CIKRG | D20: 1 | E20: 60 | F20: 150/20 | G20: 1732 | H20: 313.55333 | I20: 18.103541 | J20: 244.01333 | K20: 14.08853 | O20: =IF(I20>=80,"B","K") -> K | P20: K | R20: =(H20/G20)*100 -> 18.103541 | S20: =J20/G20*100 -> 14.08853 | U20: =IF(R20=I20,"BETUL","salah") -> BETUL | V20: =IF(K20=S20,"BETUL","SALAH") -> BETUL | W20: =IF(I20>80,"CEK KEMBALI","OKE") -> OKE | X20: =IF(K20>80,"CEK KEMBALI","OKE") -> OKE | Z20: =MIN(H20,J20) -> 244.01333 | AA20: =MIN(I20,K20) -> 14.08853 | AB20: =IF(Z20=H20,#REF!,#REF!) -> #REF! | AC20: =IF(Z20=H20,#REF!,#REF!) -> #REF! | AD20: =IF(Z20=H20,"Siang","Malam") -> Malam
A21: 8 | B21: CIKARANG | C21: LIPPO | D21: 2 | E21: 60 | F21: 150/20 | G21: 1732 | H21: 448.71241 | I21: 25.907183 | J21: 417.37669 | K21: 24.097961 | O21: =IF(I21>=80,"B","K") -> K | P21: K | R21: =(H21/G21)*100 -> 25.907183 | S21: =J21/G21*100 -> 24.097961 | U21: =IF(R21=I21,"BETUL","salah") -> BETUL | V21: =IF(K21=S21,"BETUL","SALAH") -> BETUL | W21: =IF(I21>80,"CEK KEMBALI","OKE") -> OKE | X21: =IF(K21>80,"CEK KEMBALI","OKE") -> OKE | Z21: =MIN(H21,J21) -> 417.37669 | AA21: =MIN(I21,K21) -> 24.097961 | AB21: =IF(Z21=H21,#REF!,#REF!) -> #REF! | AC21: =IF(Z21=H21,#REF!,#REF!) -> #REF! | AD21: =IF(Z21=H21,"Siang","Malam") -> Malam
A22: 9 | B22: CIKARANG | C22: JBBKA | D22: 3 | E22: 60 | F22: 150/20 | G22: 1732 | H22: 1443.179 | I22: 83.324422 | J22: 317.17751 | K22: 18.312789 | O22: =IF(I22>=80,"B","K") -> B | P22: K | R22: =(H22/G22)*100 -> 83.324422 | S22: =J22/G22*100 -> 18.312789 | U22: =IF(R22=I22,"BETUL","salah") -> BETUL | V22: =IF(K22=S22,"BETUL","SALAH") -> BETUL | W22: =IF(I22>80,"CEK KEMBALI","OKE") -> CEK KEMBALI | X22: =IF(K22>80,"CEK KEMBALI","OKE") -> OKE | Z22: =MIN(H22,J22) -> 317.17751 | AA22: =MIN(I22,K22) -> 18.312789 | AB22: =IF(Z22=H22,#REF!,#REF!) -> #REF! | AC22: =IF(Z22=H22,#REF!,#REF!) -> #REF! | AD22: =IF(Z22=H22,"Siang","Malam") -> Malam
A23: 10 | B23: BEKASI | C23: NPCLR | D23: 1 | E23: 60 | F23: 150/20 | G23: 1732 | H23: 0 | I23: 0 | J23: 0 | K23: 0 | O23: =IF(I23>=80,"B","K") -> K | P23: K | R23: =(H23/G23)*100 -> 0 | S23: =J23/G23*100 -> 0 | U23: =IF(R23=I23,"BETUL","salah") -> BETUL | V23: =IF(K23=S23,"BETUL","SALAH") -> BETUL | W23: =IF(I23>80,"CEK KEMBALI","OKE") -> OKE | X23: =IF(K23>80,"CEK KEMBALI","OKE") -> OKE | Z23: =MIN(H23,J23) -> 0 | AA23: =MIN(I23,K23) -> 0 | AB23: =IF(Z23=H23,#REF!,#REF!) -> #REF! | AC23: =IF(Z23=H23,#REF!,#REF!) -> #REF! | AD23: =IF(Z23=H23,"Siang","Malam") -> Siang
A24: 11 | B24: BEKASI | C24: NPCLR | D24: 2 | E24: 60 | F24: 150/20 | G24: 1732 | H24: 0 | I24: 0 | J24: 0 | K24: 0 | Z24: =MIN(H24,J24) -> 0 | AA24: =MIN(I24,K24) -> 0 | AB24: =IF(Z24=H24,#REF!,#REF!) -> #REF! | AC24: =IF(Z24=H24,#REF!,#REF!) -> #REF! | AD24: =IF(Z24=H24,"Siang","Malam") -> Siang
A25: 12 | B25: BEKASI | C25: NTMBN | D25: 2 | E25: 60 | F25: 150/20 | G25: 1732 | H25: 301.5279 | I25: 17.409232 | J25: 292.05193 | K25: 16.862121 | O25: =IF(I25>=80,"B","K") -> K | P25: =IF(K25>=80,"B","K") -> K | R25: =(H25/G25)*100 -> 17.409232 | S25: =J25/G25*100 -> 16.862121 | U25: =IF(R25=I25,"BETUL","salah") -> BETUL | V25: =IF(K25=S25,"BETUL","SALAH") -> BETUL | W25: =IF(I25>80,"CEK KEMBALI","OKE") -> OKE | X25: =IF(K25>80,"CEK KEMBALI","OKE") -> OKE | Z25: =MIN(H25,J25) -> 292.05193 | AA25: =MIN(I25,K25) -> 16.862121 | AB25: =IF(Z25=H25,#REF!,#REF!) -> #REF! | AC25: =IF(Z25=H25,#REF!,#REF!) -> #REF! | AD25: =IF(Z25=H25,"Siang","Malam") -> Malam
A26: 13 | B26: BEKASI | C26: SMRCN | D26: 2 | E26: 60 | F26: 150/20 | G26: 1732 | H26: 261.1384 | I26: 15.077275 | J26: 189.90957 | K26: 10.964756 | O26: =IF(I26>=80,"B","K") -> K | P26: =IF(K26>=80,"B","K") -> K | R26: =(H26/G26)*100 -> 15.077275 | S26: =J26/G26*100 -> 10.964756 | U26: =IF(R26=I26,"BETUL","salah") -> BETUL | V26: =IF(K26=S26,"BETUL","SALAH") -> BETUL | W26: =IF(I26>80,"CEK KEMBALI","OKE") -> OKE | X26: =IF(K26>80,"CEK KEMBALI","OKE") -> OKE | Z26: =MIN(H26,J26) -> 189.90957 | AA26: =MIN(I26,K26) -> 10.964756 | AB26: =IF(Z26=H26,#REF!,#REF!) -> #REF! | AC26: =IF(Z26=H26,#REF!,#REF!) -> #REF! | AD26: =IF(Z26=H26,"Siang","Malam") -> Malam
A27: 14 | B27: CIKARANG | C27: DLTMS | D27: 1 | E27: 60 | F27: 150/20 | G27: 1732 | H27: 670.41602 | I27: 38.707622 | J27: 503.15815 | K27: 29.050702 | O27: =IF(I27>=80,"B","K") -> K | P27: =IF(K27>=80,"B","K") -> K | R27: =(H27/G27)*100 -> 38.707622 | S27: =J27/G27*100 -> 29.050702 | U27: =IF(R27=I27,"BETUL","salah") -> BETUL | V27: =IF(K27=S27,"BETUL","SALAH") -> BETUL | W27: =IF(I27>80,"CEK KEMBALI","OKE") -> OKE | X27: =IF(K27>80,"CEK KEMBALI","OKE") -> OKE | Z27: =MIN(H27,J27) -> 503.15815 | AA27: =MIN(I27,K27) -> 29.050702 | AB27: =IF(Z27=H27,#REF!,#REF!) -> #REF! | AC27: =IF(Z27=H27,#REF!,#REF!) -> #REF! | AD27: =IF(Z27=H27,"Siang","Malam") -> Malam
A28: 15 | B28: CIKARANG | C28: DLTMS | D28: 2 | E28: 60 | F28: 150/20 | G28: 1732 | H28: 624.1795 | I28: 36.038078 | J28: 440.39302 | K28: 25.426848 | O28: =IF(I28>=80,"B","K") -> K | P28: =IF(K28>=80,"B","K") -> K | R28: =(H28/G28)*100 -> 36.038078 | S28: =J28/G28*100 -> 25.426848 | U28: =IF(R28=I28,"BETUL","salah") -> BETUL | V28: =IF(K28=S28,"BETUL","SALAH") -> BETUL | W28: =IF(I28>80,"CEK KEMBALI","OKE") -> OKE | X28: =IF(K28>80,"CEK KEMBALI","OKE") -> OKE | Z28: =MIN(H28,J28) -> 440.39302 | AA28: =MIN(I28,K28) -> 25.426848 | AB28: =IF(Z28=H28,#REF!,#REF!) -> #REF! | AC28: =IF(Z28=H28,#REF!,#REF!) -> #REF! | AD28: =IF(Z28=H28,"Siang","Malam") -> Malam
A29: 16 | B29: BOGOR | C29: KTLPA | D29: 1 | E29: 60 | F29: 150/20 | G29: 1732 | H29: 486.32005 | I29: 28.078525 | J29: 535.00128 | K29: 30.88922 | O29: =IF(I29>=80,"B","K") -> K | P29: =IF(K29>=80,"B","K") -> K | R29: =(H29/G29)*100 -> 28.078525 | S29: =J29/G29*100 -> 30.88922 | U29: =IF(R29=I29,"BETUL","salah") -> BETUL | V29: =IF(K29=S29,"BETUL","SALAH") -> BETUL | W29: =IF(I29>80,"CEK KEMBALI","OKE") -> OKE | X29: =IF(K29>80,"CEK KEMBALI","OKE") -> OKE | Z29: =MIN(H29,J29) -> 486.32005 | AA29: =MIN(I29,K29) -> 28.078525 | AB29: =IF(Z29=H29,#REF!,#REF!) -> #REF! | AC29: =IF(Z29=H29,#REF!,#REF!) -> #REF! | AD29: =IF(Z29=H29,"Siang","Malam") -> Siang
A30: 17 | B30: BOGOR | C30: KTLPA | D30: 2 | E30: 60 | F30: 150/20 | G30: 1732 | H30: 176.2163 | I30: 10.174151 | J30: 203.0981 | K30: 11.726218 | O30: =IF(I30>=80,"B","K") -> K | P30: =IF(K30>=80,"B","K") -> K | R30: =(H30/G30)*100 -> 10.174151 | S30: =J30/G30*100 -> 11.726218 | U30: =IF(R30=I30,"BETUL","salah") -> BETUL | V30: =IF(K30=S30,"BETUL","SALAH") -> BETUL | W30: =IF(I30>80,"CEK KEMBALI","OKE") -> OKE | X30: =IF(K30>80,"CEK KEMBALI","OKE") -> OKE | Z30: =MIN(H30,J30) -> 176.2163 | AA30: =MIN(I30,K30) -> 10.174151 | AB30: =IF(Z30=H30,#REF!,#REF!) -> #REF! | AC30: =IF(Z30=H30,#REF!,#REF!) -> #REF! | AD30: =IF(Z30=H30,"Siang","Malam") -> Siang
A31: 18 | B31: CIMAHI | C31: LGDAR | D31: 1 | E31: 60 | F31: 150/20 | G31: 1732 | H31: 430.52706 | I31: 24.85722 | J31: 451.1521 | K31: 26.048043 | O31: =IF(I31>=80,"B","K") -> K | P31: =IF(K31>=80,"B","K") -> K | R31: =(H31/G31)*100 -> 24.85722 | S31: =J31/G31*100 -> 26.048043 | U31: =IF(R31=I31,"BETUL","salah") -> BETUL | V31: =IF(K31=S31,"BETUL","SALAH") -> BETUL | W31: =IF(I31>80,"CEK KEMBALI","OKE") -> OKE | X31: =IF(K31>80,"CEK KEMBALI","OKE") -> OKE | Z31: =MIN(H31,J31) -> 430.52706 | AA31: =MIN(I31,K31) -> 24.85722 | AB31: =IF(Z31=H31,#REF!,#REF!) -> #REF! | AC31: =IF(Z31=H31,#REF!,#REF!) -> #REF! | AD31: =IF(Z31=H31,"Siang","Malam") -> Siang
A32: 19 | B32: CIREBON | C32: ARJWN | D32: 2 | E32: 30 | F32: 70/20 | G32: 866 | H32: 305.57294 | I32: 35.285559 | J32: 252.4451 | K32: 29.150705 | O32: =IF(I32>=80,"B","K") -> K | P32: =IF(K32>=80,"B","K") -> K | R32: =(H32/G32)*100 -> 35.285559 | S32: =J32/G32*100 -> 29.150705 | U32: =IF(R32=I32,"BETUL","salah") -> BETUL | V32: =IF(K32=S32,"BETUL","SALAH") -> BETUL | W32: =IF(I32>80,"CEK KEMBALI","OKE") -> OKE | X32: =IF(K32>80,"CEK KEMBALI","OKE") -> OKE | Z32: =MIN(H32,J32) -> 252.4451 | AA32: =MIN(I32,K32) -> 29.150705 | AB32: =IF(Z32=H32,#REF!,#REF!) -> #REF! | AC32: =IF(Z32=H32,#REF!,#REF!) -> #REF! | AD32: =IF(Z32=H32,"Siang","Malam") -> Malam
A33: 20 | B33: CIREBON | C33: NARJW | D33: 1 | E33: 60 | F33: 150/20 | G33: 1732 | H33: 416.72638 | I33: 24.060415 | J33: 486.09594 | K33: 28.065585 | O33: =IF(I33>=80,"B","K") -> K | P33: =IF(K33>=80,"B","K") -> K | R33: =(H33/G33)*100 -> 24.060415 | S33: =J33/G33*100 -> 28.065585 | U33: =IF(R33=I33,"BETUL","salah") -> BETUL | V33: =IF(K33=S33,"BETUL","SALAH") -> BETUL | W33: =IF(I33>80,"CEK KEMBALI","OKE") -> OKE | X33: =IF(K33>80,"CEK KEMBALI","OKE") -> OKE | Z33: =MIN(H33,J33) -> 416.72638 | AA33: =MIN(I33,K33) -> 24.060415 | AB33: =IF(Z33=H33,#REF!,#REF!) -> #REF! | AC33: =IF(Z33=H33,#REF!,#REF!) -> #REF! | AD33: =IF(Z33=H33,"Siang","Malam") -> Siang
A34: 21 | B34: INDRAMAYU | C34: CKDNG | D34: 1 | E34: 60 | F34: 150/20 | G34: 1732 | H34: 467.94746 | I34: 27.017752 | J34: 477.86586 | K34: 27.590407 | O34: =IF(I34>=80,"B","K") -> K | P34: =IF(K34>=80,"B","K") -> K | R34: =(H34/G34)*100 -> 27.017752 | S34: =J34/G34*100 -> 27.590407 | U34: =IF(R34=I34,"BETUL","salah") -> BETUL | V34: =IF(K34=S34,"BETUL","SALAH") -> BETUL | W34: =IF(I34>80,"CEK KEMBALI","OKE") -> OKE | X34: =IF(K34>80,"CEK KEMBALI","OKE") -> OKE | Z34: =MIN(H34,J34) -> 467.94746 | AA34: =MIN(I34,K34) -> 27.017752 | AB34: =IF(Z34=H34,#REF!,#REF!) -> #REF! | AC34: =IF(Z34=H34,#REF!,#REF!) -> #REF! | AD34: =IF(Z34=H34,"Siang","Malam") -> Siang
A35: 22 | B35: DEPOK | C35: CMGIS | D35: 4 | E35: 60 | F35: 150/22 | G35: 1573 | H35: 177.834 | I35: 11.305404 | J35: 169.78 | K35: 10.793389 | O35: =IF(I35>=80,"B","K") -> K | P35: =IF(K35>=80,"B","K") -> K | R35: =(H35/G35)*100 -> 11.305404 | S35: =J35/G35*100 -> 10.793389 | U35: =IF(R35=I35,"BETUL","salah") -> BETUL | V35: =IF(K35=S35,"BETUL","SALAH") -> BETUL | W35: =IF(I35>80,"CEK KEMBALI","OKE") -> OKE | X35: =IF(K35>80,"CEK KEMBALI","OKE") -> OKE | Z35: =MIN(H35,J35) -> 169.78 | AA35: =MIN(I35,K35) -> 10.793389 | AB35: =IF(Z35=H35,#REF!,#REF!) -> #REF! | AC35: =IF(Z35=H35,#REF!,#REF!) -> #REF! | AD35: =IF(Z35=H35,"Siang","Malam") -> Malam
A36: 23 | B36: DEPOK | C36: DPBR2 | D36: 3 | E36: 60 | F36: 150/20 | G36: 1732 | H36: 0 | I36: 0 | J36: 0 | K36: 0 | O36: =IF(I36>=80,"B","K") -> K | P36: =IF(K36>=80,"B","K") -> K | R36: =(H36/G36)*100 -> 0 | S36: =J36/G36*100 -> 0 | U36: =IF(R36=I36,"BETUL","salah") -> BETUL | V36: =IF(K36=S36,"BETUL","SALAH") -> BETUL | W36: =IF(I36>80,"CEK KEMBALI","OKE") -> OKE | X36: =IF(K36>80,"CEK KEMBALI","OKE") -> OKE | Z36: =MIN(H36,J36) -> 0 | AA36: =MIN(I36,K36) -> 0 | AB36: =IF(Z36=H36,#REF!,#REF!) -> #REF! | AC36: =IF(Z36=H36,#REF!,#REF!) -> #REF! | AD36: =IF(Z36=H36,"Siang","Malam") -> Siang
... A76: 63 | B76: TASIKMALAYA | C76: TSMYA | D76: 2 | E76: 60 | F76: 150/20 | G76: 1732 | H76: 237.25657 | I76: 13.698416 | J76: 244.46484 | K76: 14.114598 | O76: =IF(I76>=80,"B","K") -> K | P76: =IF(K76>=80,"B","K") -> K | R76: =(H76/G76)*100 -> 13.698416 | S76: =J76/G76*100 -> 14.114598 | U76: =IF(R76=I76,"BETUL","salah") -> BETUL | V76: =IF(K76=S76,"BETUL","SALAH") -> BETUL | W76: =IF(I76>80,"CEK KEMBALI","OKE") -> OKE | X76: =IF(K76>80,"CEK KEMBALI","OKE") -> OKE | Z76: =MIN(H76,J76) -> 237.25657 | AA76: =MIN(I76,K76) -> 13.698416 | AB76: =IF(Z76=H76,#REF!,#REF!) -> #REF! | AC76: =IF(Z76=H76,#REF!,#REF!) -> #REF! | AD76: =IF(Z76=H76,"Siang","Malam") -> Siang

Sheet  TRAFO 0% no print
B2: BEBAN TRAFO GARDU INDUK DISTRIBUSI JABAR & BANTEN
A7: LAMPIRAN XIII.1
A8: BEBAN NOL TRAFO GARDU INDUK DISTRIBUSI JAWA BARAT
A9: =' TRAFO 30% no print'!A9:K9 -> APRIL 2022
A11: N0 | B11: UP3 | C11: GI | D11: TRF | E11: DAYA | F11: TGN | G11: I-NOM | H11: April | L11: KETERANGAN
H12: Siang | J12: Malam
F13: (kV) | H13: A | I13: % | J13: A | K13: % | Z13: A | AA13: % | AB13: TEG | AC13: TANGGAL | AD13: SIANG/MALAM
A14: 1 | B14: BEKASI | C14: NPCLR | D14: 1 | E14: 60 | F14: 150/20 | G14: 1732 | H14: 0 | I14: 0 | J14: 0 | K14: 0 | O14: =IF(I14>=80,"B","K") -> K | P14: =IF(K14>=80,"B","K") -> K | R14: =(H14/G14)*100 -> 0 | S14: =J14/G14*100 -> 0 | U14: =IF(R14=I14,"BETUL","salah") -> BETUL | V14: =IF(K14=S14,"BETUL","SALAH") -> BETUL | W14: =IF(I14>80,"CEK KEMBALI","OKE") -> OKE | X14: =IF(K14>80,"CEK KEMBALI","OKE") -> OKE | Z14: =MAX(H14,J14) -> 0 | AA14: =MAX(I14,K14) -> 0 | AB14: =IF(Z14=H14,#REF!,#REF!) -> #REF! | AC14: =IF(Z14=H14,#REF!,#REF!) -> #REF! | AD14: =IF(Z14=H14,"Siang","Malam") -> Siang
A15: 2 | B15: BEKASI | C15: NPCLR | D15: 2 | E15: 60 | F15: 150/20 | G15: 1732 | H15: 0 | I15: 0 | J15: 0 | K15: 0 | O15: =IF(I15>=80,"B","K") -> K | P15: =IF(K15>=80,"B","K") -> K | R15: =(H15/G15)*100 -> 0 | S15: =J15/G15*100 -> 0 | U15: =IF(R15=I15,"BETUL","salah") -> BETUL | V15: =IF(K15=S15,"BETUL","SALAH") -> BETUL | W15: =IF(I15>80,"CEK KEMBALI","OKE") -> OKE | X15: =IF(K15>80,"CEK KEMBALI","OKE") -> OKE | Z15: =MAX(H15,J15) -> 0 | AA15: =MAX(I15,K15) -> 0 | AB15: =IF(Z15=H15,#REF!,#REF!) -> #REF! | AC15: =IF(Z15=H15,#REF!,#REF!) -> #REF! | AD15: =IF(Z15=H15,"Siang","Malam") -> Siang
A16: 3 | B16: DEPOK | C16: DPBR2 | D16: 3 | E16: 60 | F16: 150/20 | G16: 1732 | H16: 0 | I16: 0 | J16: 0 | K16: 0 | O16: =IF(I16>=80,"B","K") -> K | P16: =IF(K16>=80,"B","K") -> K | R16: =(H16/G16)*100 -> 0 | S16: =J16/G16*100 -> 0 | U16: =IF(R16=I16,"BETUL","salah") -> BETUL | V16: =IF(K16=S16,"BETUL","SALAH") -> BETUL | W16: =IF(I16>80,"CEK KEMBALI","OKE") -> OKE | X16: =IF(K16>80,"CEK KEMBALI","OKE") -> OKE | Z16: =MAX(H16,J16) -> 0 | AA16: =MAX(I16,K16) -> 0 | AB16: =IF(Z16=H16,#REF!,#REF!) -> #REF! | AC16: =IF(Z16=H16,#REF!,#REF!) -> #REF! | AD16: =IF(Z16=H16,"Siang","Malam") -> Siang
A17: 4 | B17: MAJALAYA | C17: CKSKA | D17: 4 | E17: 60 | F17: 150/20 | G17: 1732 | H17: 0 | I17: 0 | J17: 0 | K17: 0 | O17: =IF(I17>=80,"B","K") -> K | P17: =IF(K17>=80,"B","K") -> K | R17: =(H17/G17)*100 -> 0 | S17: =J17/G17*100 -> 0 | U17: =IF(R17=I17,"BETUL","salah") -> BETUL | V17: =IF(K17=S17,"BETUL","SALAH") -> BETUL | W17: =IF(I17>80,"CEK KEMBALI","OKE") -> OKE | X17: =IF(K17>80,"CEK KEMBALI","OKE") -> OKE | Z17: =MAX(H17,J17) -> 0 | AA17: =MAX(I17,K17) -> 0 | AB17: =IF(Z17=H17,#REF!,#REF!) -> #REF! | AC17: =IF(Z17=H17,#REF!,#REF!) -> #REF! | AD17: =IF(Z17=H17,"Siang","Malam") -> Siang
A18: 5 | B18: PURWAKARTA | C18: CRBRU | D18: 4 | E18: 60 | F18: 150/20 | G18: 1732 | H18: 0 | I18: 0 | J18: 0 | K18: 0 | O18: =IF(I18>=80,"B","K") -> K | P18: =IF(K18>=80,"B","K") -> K | R18: =(H18/G18)*100 -> 0 | S18: =J18/G18*100 -> 0 | U18: =IF(R18=I18,"BETUL","salah") -> BETUL | V18: =IF(K18=S18,"BETUL","SALAH") -> BETUL | W18: =IF(I18>80,"CEK KEMBALI","OKE") -> OKE | X18: =IF(K18>80,"CEK KEMBALI","OKE") -> OKE | Z18: =MAX(H18,J18) -> 0 | AA18: =MAX(I18,K18) -> 0 | AB18: =IF(Z18=H18,#REF!,#REF!) -> #REF! | AC18: =IF(Z18=H18,#REF!,#REF!) -> #REF! | AD18: =IF(Z18=H18,"Siang","Malam") -> Siang
A19: 6 | B19: SUKABUMI | C19: PRATU | D19: 1 | E19: 30 | F19: 70/20 | G19: 866 | H19: 0 | I19: 0 | J19: 0 | K19: 0 | O19: =IF(I19>=80,"B","K") -> K | P19: =IF(K19>=80,"B","K") -> K | R19: =(H19/G19)*100 -> 0 | S19: =J19/G19*100 -> 0 | U19: =IF(R19=I19,"BETUL","salah") -> BETUL | V19: =IF(K19=S19,"BETUL","SALAH") -> BETUL | W19: =IF(I19>80,"CEK KEMBALI","OKE") -> OKE | X19: =IF(K19>80,"CEK KEMBALI","OKE") -> OKE | Z19: =MAX(H19,J19) -> 0 | AA19: =MAX(I19,K19) -> 0 | AB19: =IF(Z19=H19,#REF!,#REF!) -> #REF! | AC19: =IF(Z19=H19,#REF!,#REF!) -> #REF! | AD19: =IF(Z19=H19,"Siang","Malam") -> Siang
A20: 7 | B20: SUMEDANG | C20: SMDNG | D20: 1 | E20: 10 | F20: 70/20 | G20: 288 | H20: 0 | I20: 0 | J20: 0 | K20: 0 | O20: =IF(I20>=80,"B","K") -> K | P20: =IF(K20>=80,"B","K") -> K | R20: =(H20/G20)*100 -> 0 | S20: =J20/G20*100 -> 0 | U20: =IF(R20=I20,"BETUL","salah") -> BETUL | V20: =IF(K20=S20,"BETUL","SALAH") -> BETUL | W20: =IF(I20>80,"CEK KEMBALI","OKE") -> OKE | X20: =IF(K20>80,"CEK KEMBALI","OKE") -> OKE | Z20: =MAX(H20,J20) -> 0 | AA20: =MAX(I20,K20) -> 0 | AB20: =IF(Z20=H20,#REF!,#REF!) -> #REF! | AC20: =IF(Z20=H20,#REF!,#REF!) -> #REF! | AD20: =IF(Z20=H20,"Siang","Malam") -> Siang

Sheet  TRAFO 80% PRINT
B2: BEBAN TRAFO GARDU INDUK DISTRIBUSI JABAR & BANTEN
A6: LAMPIRAN XI.1
A8: BEBAN TRAFO GARDU INDUK ≥ 80% UNIT INDUK DISTRIBUSI JAWA BARAT
A9: APRIL 2022
A11: N0 | B11: UP3 | C11: GI | D11: TRF | E11: DAYA | F11: TGN | G11: I-NOM | H11: April | K11: KETERANGAN
H12: Beban | J12: Siang
F13: (kV) | H13: A | I13: % | J13: Malam
A14: 1 | B14: =' TRAFO 80% no print '!B14 -> BEKASI | C14: =' TRAFO 80% no print '!C14 -> BKASI | D14: =' TRAFO 80% no print '!D14 -> 1 | E14: =' TRAFO 80% no print '!E14 -> 60 | F14: =' TRAFO 80% no print '!F14 -> 150/20 | G14: =' TRAFO 80% no print '!G14 -> 1732 | H14: =' TRAFO 80% no print '!Z14 -> 1413.2721 | I14: =' TRAFO 80% no print '!AA14 -> 81.597694 | J14: =' TRAFO 80% no print '!AD14 -> Malam | K14: =' TRAFO 80% no print '!L14 -> Kawaasan industri & umum Bekasi | N14: =IF(#REF!>=80,"B","K") -> #REF! | O14: =IF(#REF!>=80,"B","K") -> #REF! | Q14: =(#REF!/G14)*100 -> #REF! | R14: =#REF!/G14*100 -> #REF! | T14: =IF(Q14=#REF!,"BETUL","salah") -> #REF! | U14: =IF(#REF!=R14,"BETUL","SALAH") -> #REF! | V14: =IF(#REF!>80,"CEK KEMBALI","OKE") -> #REF! | W14: =IF(#REF!>80,"CEK KEMBALI","OKE") -> #REF!
A15: 2 | B15: =' TRAFO 80% no print '!B15 -> CIKARANG | C15: =' TRAFO 80% no print '!C15 -> CBATU | D15: =' TRAFO 80% no print '!D15 -> 2 | E15: =' TRAFO 80% no print '!E15 -> 60 | F15: =' TRAFO 80% no print '!F15 -> 150/20 | G15: =' TRAFO 80% no print '!G15 -> 1732 | H15: =' TRAFO 80% no print '!Z15 -> 1466.1169 | I15: =' TRAFO 80% no print '!AA15 -> 84.64878 | J15: =' TRAFO 80% no print '!AD15 -> Malam | K15: =' TRAFO 80% no print '!L15 -> Wilayah Umum Cibatu,Sukamanah, Cicau | N15: =IF(#REF!>=80,"B","K") -> #REF! | O15: =IF(#REF!>=80,"B","K") -> #REF! | Q15: =(#REF!/G15)*100 -> #REF! | R15: =#REF!/G15*100 -> #REF! | T15: #REF! | U15: =IF(#REF!=R15,"BETUL","SALAH") -> #REF! | V15: =IF(#REF!>80,"CEK KEMBALI","OKE") -> #REF! | W15: =IF(#REF!>80,"CEK KEMBALI","OKE") -> #REF!
A16: 3 | B16: =' TRAFO 80% no print '!B16 -> CIKARANG | C16: =' TRAFO 80% no print '!C16 -> GDMKR | D16: =' TRAFO 80% no print '!D16 -> 2 | E16: =' TRAFO 80% no print '!E16 -> 60 | F16: =' TRAFO 80% no print '!F16 -> 150/20 | G16: =' TRAFO 80% no print '!G16 -> 1732 | H16: =' TRAFO 80% no print '!Z16 -> 1564.3778 | I16: =' TRAFO 80% no print '!AA16 -> 90.322047 | J16: =' TRAFO 80% no print '!AD16 -> Siang | K16: =' TRAFO 80% no print '!L16 -> Kawasan industri dan Cikarang Bekasi | N16: =IF(#REF!>=80,"B","K") -> #REF! | O16: =IF(#REF!>=80,"B","K") -> #REF! | Q16: =(#REF!/G16)*100 -> #REF! | R16: =#REF!/G16*100 -> #REF! | T16: =IF(Q16=#REF!,"BETUL","salah") -> #REF! | U16: #REF! | V16: =IF(#REF!>80,"CEK KEMBALI","OKE") -> #REF! | W16: =IF(#REF!>80,"CEK KEMBALI","OKE") -> #REF!
A17: 4 | B17: =' TRAFO 80% no print '!B17 -> CIKARANG | C17: =' TRAFO 80% no print '!C17 -> GDMKR | D17: =' TRAFO 80% no print '!D17 -> 3 | E17: =' TRAFO 80% no print '!E17 -> 60 | F17: =' TRAFO 80% no print '!F17 -> 150/20 | G17: =' TRAFO 80% no print '!G17 -> 1732 | H17: =' TRAFO 80% no print '!Z17 -> 1633.315 | I17: =' TRAFO 80% no print '!AA17 -> 94.302251 | J17: =' TRAFO 80% no print '!AD17 -> Siang | K17: =' TRAFO 80% no print '!L17 -> Kawasan industri dan Cikarang Bekasi | N17: =IF(#REF!>=80,"B","K") -> #REF! | O17: #REF! | Q17: =(#REF!/G17)*100 -> #REF! | R17: =#REF!/G17*100 -> #REF! | T17: #REF! | U17: =IF(#REF!=R17,"BETUL","SALAH") -> #REF! | V17: =IF(#REF!>80,"CEK KEMBALI","OKE") -> #REF! | W17: =IF(#REF!>80,"CEK KEMBALI","OKE") -> #REF!
A18: 5 | B18: =' TRAFO 80% no print '!B18 -> CIKARANG | C18: =' TRAFO 80% no print '!C18 -> JBBKA | D18: =' TRAFO 80% no print '!D18 -> 2 | E18: =' TRAFO 80% no print '!E18 -> 60 | F18: =' TRAFO 80% no print '!F18 -> 150/20 | G18: =' TRAFO 80% no print '!G18 -> 1732 | H18: =' TRAFO 80% no print '!Z18 -> 1404.3032 | I18: =' TRAFO 80% no print '!AA18 -> 81.07986 | J18: =' TRAFO 80% no print '!AD18 -> Siang | K18: =' TRAFO 80% no print '!L18 -> Kawasan industri Jababeka Bekasi | N18: =IF(#REF!>=80,"B","K") -> #REF! | O18: =IF(#REF!>=80,"B","K") -> #REF! | Q18: =(#REF!/G18)*100 -> #REF! | R18: =#REF!/G18*100 -> #REF! | T18: =IF(Q18=#REF!,"BETUL","salah") -> #REF! | U18: =IF(#REF!=R18,"BETUL","SALAH") -> #REF! | V18: #REF! | W18: =IF(#REF!>80,"CEK KEMBALI","OKE") -> #REF!
A19: 6 | B19: =' TRAFO 80% no print '!B19 -> CIKARANG | C19: =' TRAFO 80% no print '!C19 -> JBBKA | D19: =' TRAFO 80% no print '!D19 -> 3 | E19: =' TRAFO 80% no print '!E19 -> 60 | F19: =' TRAFO 80% no print '!F19 -> 150/20 | G19: =' TRAFO 80% no print '!G19 -> 1732 | H19: =' TRAFO 80% no print '!Z19 -> 1443.179 | I19: =' TRAFO 80% no print '!AA19 -> 83.324422 | J19: =' TRAFO 80% no print '!AD19 -> Siang | K19: =' TRAFO 80% no print '!L19 -> Kawasan industri Jababeka Bekasi | N19: =IF(#REF!>=80,"B","K") -> #REF! | O19: =IF(#REF!>=80,"B","K") -> #REF! | Q19: =(#REF!/G19)*100 -> #REF! | R19: =#REF!/G19*100 -> #REF! | T19: =IF(Q19=#REF!,"BETUL","salah") -> #REF! | U19: =IF(#REF!=R19,"BETUL","SALAH") -> #REF! | V19: =IF(#REF!>80,"CEK KEMBALI","OKE") -> #REF! | W19: =IF(#REF!>80,"CEK KEMBALI","OKE") -> #REF!
A20: 7 | B20: =' TRAFO 80% no print '!B20 -> CIKARANG | C20: =' TRAFO 80% no print '!C20 -> JBBKA | D20: =' TRAFO 80% no print '!D20 -> 4 | E20: =' TRAFO 80% no print '!E20 -> 60 | F20: =' TRAFO 80% no print '!F20 -> 150/20 | G20: =' TRAFO 80% no print '!G20 -> 1732 | H20: =' TRAFO 80% no print '!Z20 -> 1436.2874 | I20: =' TRAFO 80% no print '!AA20 -> 82.926522 | J20: =' TRAFO 80% no print '!AD20 -> Siang | K20: =' TRAFO 80% no print '!L20 -> Kawasan industri Jababeka Bekasi | N20: =IF(#REF!>=80,"B","K") -> #REF! | O20: =IF(#REF!>=80,"B","K") -> #REF! | Q20: =(#REF!/G20)*100 -> #REF! | R20: =#REF!/G20*100 -> #REF! | T20: =IF(Q20=#REF!,"BETUL","salah") -> #REF! | U20: =IF(#REF!=R20,"BETUL","SALAH") -> #REF! | V20: =IF(#REF!>80,"CEK KEMBALI","OKE") -> #REF! | W20: =IF(#REF!>80,"CEK KEMBALI","OKE") -> #REF!
A21: 8 | B21: =' TRAFO 80% no print '!B21 -> BEKASI | C21: =' TRAFO 80% no print '!C21 -> PCBRU | D21: =' TRAFO 80% no print '!D21 -> 1 | E21: =' TRAFO 80% no print '!E21 -> 60 | F21: =' TRAFO 80% no print '!F21 -> 150/20 | G21: =' TRAFO 80% no print '!G21 -> 1732 | H21: =' TRAFO 80% no print '!Z21 -> 1568.1989 | I21: =' TRAFO 80% no print '!AA21 -> 90.542661 | J21: =' TRAFO 80% no print '!AD21 -> Siang | K21: =' TRAFO 80% no print '!L21 -> Wilayah Kalimalang, Margahayu dan Bulak Kapal | N21: =IF(#REF!>=80,"B","K") -> #REF! | O21: =IF(#REF!>=80,"B","K") -> #REF! | Q21: =(#REF!/G21)*100 -> #REF! | R21: =#REF!/G21*100 -> #REF! | T21: =IF(Q21=#REF!,"BETUL","salah") -> #REF! | U21: #REF! | V21: =IF(#REF!>80,"CEK KEMBALI","OKE") -> #REF! | W21: =IF(#REF!>80,"CEK KEMBALI","OKE") -> #REF!
A22: 9 | B22: =' TRAFO 80% no print '!B22 -> BEKASI | C22: =' TRAFO 80% no print '!C22 -> PCBRU | D22: =' TRAFO 80% no print '!D22 -> 3 | E22: =' TRAFO 80% no print '!E22 -> 60 | F22: =' TRAFO 80% no print '!F22 -> 150/20 | G22: =' TRAFO 80% no print '!G22 -> 1732 | H22: =' TRAFO 80% no print '!Z22 -> 1443.6778 | I22: =' TRAFO 80% no print '!AA22 -> 83.35322 | J22: =' TRAFO 80% no print '!AD22 -> Siang | K22: =' TRAFO 80% no print '!L22 -> Wilayah Bekasi kota, Kejaksaan, Polres | N22: =IF(#REF!>=80,"B","K") -> #REF! | O22: =IF(#REF!>=80,"B","K") -> #REF! | Q22: =(#REF!/G22)*100 -> #REF! | R22: =#REF!/G22*100 -> #REF! | T22: =IF(Q22=#REF!,"BETUL","salah") -> #REF! | U22: =IF(#REF!=R22,"BETUL","SALAH") -> #REF! | V22: =IF(#REF!>80,"CEK KEMBALI","OKE") -> #REF! | W22: =IF(#REF!>80,"CEK KEMBALI","OKE") -> #REF!
A23: 10 | B23: =' TRAFO 80% no print '!B23 -> BEKASI | C23: =' TRAFO 80% no print '!C23 -> TMBUN | D23: =' TRAFO 80% no print '!D23 -> 2 | E23: =' TRAFO 80% no print '!E23 -> 60 | F23: =' TRAFO 80% no print '!F23 -> 150/20 | G23: =' TRAFO 80% no print '!G23 -> 1732 | H23: =' TRAFO 80% no print '!Z23 -> 1447.7187 | I23: =' TRAFO 80% no print '!AA23 -> 83.586528 | J23: =' TRAFO 80% no print '!AD23 -> Siang | K23: =' TRAFO 80% no print '!L23 -> Wilayah Kota Legenda dan Bekasi Timur | N23: =IF(#REF!>=80,"B","K") -> #REF! | O23: =IF(#REF!>=80,"B","K") -> #REF! | Q23: =(#REF!/G23)*100 -> #REF! | R23: =#REF!/G23*100 -> #REF! | T23: =IF(Q23=#REF!,"BETUL","salah") -> #REF! | U23: =IF(#REF!=R23,"BETUL","SALAH") -> #REF! | V23: =IF(#REF!>80,"CEK KEMBALI","OKE") -> #REF! | W23: =IF(#REF!>80,"CEK KEMBALI","OKE") -> #REF!
A24: 11 | B24: =' TRAFO 80% no print '!B24 -> BEKASI | C24: =' TRAFO 80% no print '!C24 -> TMBUN | D24: =' TRAFO 80% no print '!D24 -> 3 | E24: =' TRAFO 80% no print '!E24 -> 60 | F24: =' TRAFO 80% no print '!F24 -> 150/20 | G24: =' TRAFO 80% no print '!G24 -> 1732 | H24: =' TRAFO 80% no print '!Z24 -> 1405.2771 | I24: =' TRAFO 80% no print '!AA24 -> 81.136089 | J24: =' TRAFO 80% no print '!AD24 -> Siang | K24: =' TRAFO 80% no print '!L24 -> Wilayah Kota Legenda dan Bekasi Timur | N24: =IF(#REF!>=80,"B","K") -> #REF! | O24: =IF(#REF!>=80,"B","K") -> #REF! | Q24: =(#REF!/G24)*100 -> #REF! | R24: =#REF!/G24*100 -> #REF! | T24: =IF(Q24=#REF!,"BETUL","salah") -> #REF! | U24: =IF(#REF!=R24,"BETUL","SALAH") -> #REF! | V24: =IF(#REF!>80,"CEK KEMBALI","OKE") -> #REF! | W24: =IF(#REF!>80,"CEK KEMBALI","OKE") -> #REF!
A25: 12 | B25: =' TRAFO 80% no print '!B25 -> BEKASI | C25: =' TRAFO 80% no print '!C25 -> TMBUN | D25: =' TRAFO 80% no print '!D25 -> 5 | E25: =' TRAFO 80% no print '!E25 -> 60 | F25: =' TRAFO 80% no print '!F25 -> 150/20 | G25: =' TRAFO 80% no print '!G25 -> 1732 | H25: =' TRAFO 80% no print '!Z25 -> 1414.1236 | I25: =' TRAFO 80% no print '!AA25 -> 81.64686 | J25: =' TRAFO 80% no print '!AD25 -> Malam | K25: =' TRAFO 80% no print '!L25 -> Wilayah Kota Legenda dan Bekasi Timur | N25: =IF(#REF!>=80,"B","K") -> #REF! | O25: #REF! | Q25: =(#REF!/G25)*100 -> #REF! | R25: =#REF!/G25*100 -> #REF! | T25: =IF(Q25=#REF!,"BETUL","salah") -> #REF! | U25: =IF(#REF!=R25,"BETUL","SALAH") -> #REF! | V25: =IF(#REF!>80,"CEK KEMBALI","OKE") -> #REF! | W25: =IF(#REF!>80,"CEK KEMBALI","OKE") -> #REF!
A26: 13 | B26: =' TRAFO 80% no print '!B26 -> BOGOR | C26: =' TRAFO 80% no print '!C26 -> BGBRU | D26: =' TRAFO 80% no print '!D26 -> 6 | E26: =' TRAFO 80% no print '!E26 -> 60 | F26: =' TRAFO 80% no print '!F26 -> 150/20 | G26: =' TRAFO 80% no print '!G26 -> 1732 | H26: =' TRAFO 80% no print '!Z26 -> 1613.3788 | I26: =' TRAFO 80% no print '!AA26 -> 93.1512 | J26: =' TRAFO 80% no print '!AD26 -> Siang | K26: =' TRAFO 80% no print '!L26 -> Wilayah industri & umum Bogor Barat | N26: =IF(#REF!>=80,"B","K") -> #REF! | O26: =IF(#REF!>=80,"B","K") -> #REF! | Q26: =(#REF!/G26)*100 -> #REF! | R26: =#REF!/G26*100 -> #REF! | T26: =IF(Q26=#REF!,"BETUL","salah") -> #REF! | U26: =IF(#REF!=R26,"BETUL","SALAH") -> #REF! | V26: =IF(#REF!>80,"CEK KEMBALI","OKE") -> #REF! | W26: =IF(#REF!>80,"CEK KEMBALI","OKE") -> #REF!
A27: 14 | B27: =' TRAFO 80% no print '!B27 -> BOGOR | C27: =' TRAFO 80% no print '!C27 -> BUNAR | D27: =' TRAFO 80% no print '!D27 -> 1 | E27: =' TRAFO 80% no print '!E27 -> 30 | F27: =' TRAFO 80% no print '!F27 -> 70/20 | G27: =' TRAFO 80% no print '!G27 -> 866 | H27: =' TRAFO 80% no print '!Z27 -> 726.61928 | I27: =' TRAFO 80% no print '!AA27 -> 83.905229 | J27: =' TRAFO 80% no print '!AD27 -> Malam | K27: =' TRAFO 80% no print '!L27 -> Wilayah Bunar Bogor | N27: =IF(#REF!>=80,"B","K") -> #REF! | O27: =IF(#REF!>=80,"B","K") -> #REF! | Q27: =(#REF!/G27)*100 -> #REF! | R27: =#REF!/G27*100 -> #REF! | T27: =IF(Q27=#REF!,"BETUL","salah") -> #REF! | U27: =IF(#REF!=R27,"BETUL","SALAH") -> #REF! | V27: =IF(#REF!>80,"CEK KEMBALI","OKE") -> #REF! | W27: #REF!
A28: 15 | B28: =' TRAFO 80% no print '!B28 -> BOGOR | C28: =' TRAFO 80% no print '!C28 -> KRCAK | D28: =' TRAFO 80% no print '!D28 -> 1 | E28: =' TRAFO 80% no print '!E28 -> 10 | F28: =' TRAFO 80% no print '!F28 -> 70/20 | G28: =' TRAFO 80% no print '!G28 -> 288 | H28: =' TRAFO 80% no print '!Z28 -> 253.65722 | I28: =' TRAFO 80% no print '!AA28 -> 88.075422 | J28: =' TRAFO 80% no print '!AD28 -> Malam | K28: =' TRAFO 80% no print '!L28 -> Wilayah umum Kracak Bogor | N28: =IF(#REF!>=80,"B","K") -> #REF! | O28: =IF(#REF!>=80,"B","K") -> #REF! | Q28: =(#REF!/G28)*100 -> #REF! | R28: =#REF!/G28*100 -> #REF! | T28: =IF(Q28=#REF!,"BETUL","salah") -> #REF! | U28: =IF(#REF!=R28,"BETUL","SALAH") -> #REF! | V28: =IF(#REF!>80,"CEK KEMBALI","OKE") -> #REF! | W28: =IF(#REF!>80,"CEK KEMBALI","OKE") -> #REF!
A29: 16 | B29: =' TRAFO 80% no print '!B29 -> GUNUNG PUTRI | C29: =' TRAFO 80% no print '!C29 -> CIBNG | D29: =' TRAFO 80% no print '!D29 -> 3 | E29: =' TRAFO 80% no print '!E29 -> 60 | F29: =' TRAFO 80% no print '!F29 -> 150/20 | G29: =' TRAFO 80% no print '!G29 -> 1732 | H29: =' TRAFO 80% no print '!Z29 -> 1449.2935 | I29: =' TRAFO 80% no print '!AA29 -> 83.677454 | J29: =' TRAFO 80% no print '!AD29 -> Siang | K29: =' TRAFO 80% no print '!L29 -> Kawsan industri & umum Cibinong Bogor | N29: =IF(#REF!>=80,"B","K") -> #REF! | O29: =IF(#REF!>=80,"B","K") -> #REF! | Q29: =(#REF!/G29)*100 -> #REF! | R29: =#REF!/G29*100 -> #REF! | T29: =IF(Q29=#REF!,"BETUL","salah") -> #REF! | U29: =IF(#REF!=R29,"BETUL","SALAH") -> #REF! | V29: =IF(#REF!>80,"CEK KEMBALI","OKE") -> #REF! | W29: =IF(#REF!>80,"CEK KEMBALI","OKE") -> #REF!
A30: 17 | B30: =' TRAFO 80% no print '!B30 -> GUNUNG PUTRI | C30: =' TRAFO 80% no print '!C30 -> CIBNG | D30: =' TRAFO 80% no print '!D30 -> 5 | E30: =' TRAFO 80% no print '!E30 -> 60 | F30: =' TRAFO 80% no print '!F30 -> 150/20 | G30: =' TRAFO 80% no print '!G30 -> 1732 | H30: =' TRAFO 80% no print '!Z30 -> 1594.3803 | I30: =' TRAFO 80% no print '!AA30 -> 92.054292 | J30: =' TRAFO 80% no print '!AD30 -> Siang | K30: =' TRAFO 80% no print '!L30 -> Kawsan industri & umum Cibinong Bogor | N30: =IF(#REF!>=80,"B","K") -> #REF! | O30: =IF(#REF!>=80,"B","K") -> #REF! | Q30: =(#REF!/G30)*100 -> #REF! | R30: =#REF!/G30*100 -> #REF! | T30: =IF(Q30=#REF!,"BETUL","salah") -> #REF! | U30: =IF(#REF!=R30,"BETUL","SALAH") -> #REF! | V30: =IF(#REF!>80,"CEK KEMBALI","OKE") -> #REF! | W30: =IF(#REF!>80,"CEK KEMBALI","OKE") -> #REF!
A31: 18 | B31: =' TRAFO 80% no print '!B31 -> GUNUNG PUTRI | C31: =' TRAFO 80% no print '!C31 -> SNTUL | D31: =' TRAFO 80% no print '!D31 -> 3 | E31: =' TRAFO 80% no print '!E31 -> 60 | F31: =' TRAFO 80% no print '!F31 -> 150/20 | G31: =' TRAFO 80% no print '!G31 -> 1732 | H31: =' TRAFO 80% no print '!Z31 -> 1731.1565 | I31: =' TRAFO 80% no print '!AA31 -> 99.951299 | J31: =' TRAFO 80% no print '!AD31 -> Siang | K31: =' TRAFO 80% no print '!L31 -> Wilayah umum Sentul | N31: =IF(#REF!>=80,"B","K") -> #REF! | O31: =IF(#REF!>=80,"B","K") -> #REF! | Q31: =(#REF!/G31)*100 -> #REF! | R31: =#REF!/G31*100 -> #REF! | T31: =IF(Q31=#REF!,"BETUL","salah") -> #REF! | U31: =IF(#REF!=R31,"BETUL","SALAH") -> #REF! | V31: =IF(#REF!>80,"CEK KEMBALI","OKE") -> #REF! | W31: =IF(#REF!>80,"CEK KEMBALI","OKE") -> #REF!
A32: 19 | B32: =' TRAFO 80% no print '!B32 -> GUNUNG PUTRI | C32: =' TRAFO 80% no print '!C32 -> SNTUL | D32: =' TRAFO 80% no print '!D32 -> 4 | E32: =' TRAFO 80% no print '!E32 -> 60 | F32: =' TRAFO 80% no print '!F32 -> 150/20 | G32: =' TRAFO 80% no print '!G32 -> 1732 | H32: =' TRAFO 80% no print '!Z32 -> 1617.529 | I32: =' TRAFO 80% no print '!AA32 -> 93.390821 | J32: =' TRAFO 80% no print '!AD32 -> Siang | K32: =' TRAFO 80% no print '!L32 -> Wilayah umum Sentul | N32: =IF(#REF!>=80,"B","K") -> #REF! | O32: =IF(#REF!>=80,"B","K") -> #REF! | Q32: =(#REF!/G32)*100 -> #REF! | R32: =#REF!/G32*100 -> #REF! | T32: =IF(Q32=#REF!,"BETUL","salah") -> #REF! | U32: =IF(#REF!=R32,"BETUL","SALAH") -> #REF! | V32: =IF(#REF!>80,"CEK KEMBALI","OKE") -> #REF! | W32: =IF(#REF!>80,"CEK KEMBALI","OKE") -> #REF!
A33: 20 | B33: =' TRAFO 80% no print '!B33 -> CIMAHI | C33: =' TRAFO 80% no print '!C33 -> PDLRU | D33: =' TRAFO 80% no print '!D33 -> 4 | E33: =' TRAFO 80% no print '!E33 -> 60 | F33: =' TRAFO 80% no print '!F33 -> 150/20 | G33: =' TRAFO 80% no print '!G33 -> 1732 | H33: =' TRAFO 80% no print '!Z33 -> 1517.5601 | I33: =' TRAFO 80% no print '!AA33 -> 87.618946 | J33: =' TRAFO 80% no print '!AD33 -> Siang | K33: =' TRAFO 80% no print '!L33 -> Padalarang,Cimahi kota,Cangkorah | N33: =IF(#REF!>=80,"B","K") -> #REF! | O33: =IF(#REF!>=80,"B","K") -> #REF! | Q33: =(#REF!/G33)*100 -> #REF! | R33: =#REF!/G33*100 -> #REF! | T33: =IF(Q33=#REF!,"BETUL","salah") -> #REF! | U33: =IF(#REF!=R33,"BETUL","SALAH") -> #REF! | V33: =IF(#REF!>80,"CEK KEMBALI","OKE") -> #REF! | W33: =IF(#REF!>80,"CEK KEMBALI","OKE") -> #REF!
A34: 21 | B34: =' TRAFO 80% no print '!B34 -> CIREBON | C34: =' TRAFO 80% no print '!C34 -> ARJWN | D34: =' TRAFO 80% no print '!D34 -> 1 | E34: =' TRAFO 80% no print '!E34 -> 30 | F34: =' TRAFO 80% no print '!F34 -> 70/20 | G34: =' TRAFO 80% no print '!G34 -> 866 | H34: =' TRAFO 80% no print '!Z34 -> 760.74591 | I34: =' TRAFO 80% no print '!AA34 -> 87.845948 | J34: =' TRAFO 80% no print '!AD34 -> Siang | K34: =' TRAFO 80% no print '!L34 -> Wilayah umum arjawinangun, Palimanan , dskt | N34: =IF(#REF!>=80,"B","K") -> #REF! | O34: =IF(#REF!>=80,"B","K") -> #REF! | Q34: =(#REF!/G34)*100 -> #REF! | R34: =#REF!/G34*100 -> #REF! | T34: =IF(Q34=#REF!,"BETUL","salah") -> #REF! | U34: =IF(#REF!=R34,"BETUL","SALAH") -> #REF! | V34: =IF(#REF!>80,"CEK KEMBALI","OKE") -> #REF! | W34: =IF(#REF!>80,"CEK KEMBALI","OKE") -> #REF!
A35: 22 | B35: =' TRAFO 80% no print '!B35 -> CIREBON | C35: =' TRAFO 80% no print '!C35 -> BBKAN | D35: =' TRAFO 80% no print '!D35 -> 3 | E35: =' TRAFO 80% no print '!E35 -> 30 | F35: =' TRAFO 80% no print '!F35 -> 70/20 | G35: =' TRAFO 80% no print '!G35 -> 866 | H35: =' TRAFO 80% no print '!Z35 -> 786.05306 | I35: =' TRAFO 80% no print '!AA35 -> 90.768252 | J35: =' TRAFO 80% no print '!AD35 -> Malam | K35: =' TRAFO 80% no print '!L35 -> Wilayah Sindang laut, Babakan | N35: =IF(#REF!>=80,"B","K") -> #REF! | O35: =IF(#REF!>=80,"B","K") -> #REF! | Q35: =(#REF!/G35)*100 -> #REF! | R35: =#REF!/G35*100 -> #REF! | T35: =IF(Q35=#REF!,"BETUL","salah") -> #REF! | U35: =IF(#REF!=R35,"BETUL","SALAH") -> #REF! | V35: =IF(#REF!>80,"CEK KEMBALI","OKE") -> #REF! | W35: =IF(#REF!>80,"CEK KEMBALI","OKE") -> #REF!
A36: 23 | B36: =' TRAFO 80% no print '!B36 -> INDRAMAYU | C36: =' TRAFO 80% no print '!C36 -> IDMYU | D36: =' TRAFO 80% no print '!D36 -> 1 | E36: =' TRAFO 80% no print '!E36 -> 30 | F36: =' TRAFO 80% no print '!F36 -> 70/19 | G36: =' TRAFO 80% no print '!G36 -> 866 | H36: =' TRAFO 80% no print '!Z36 -> 745.59875 | I36: =' TRAFO 80% no print '!AA36 -> 86.096854 | J36: =' TRAFO 80% no print '!AD36 -> Siang | K36: =' TRAFO 80% no print '!L36 -> Wilayah Indramayu,Balongan | N36: =IF(#REF!>=80,"B","K") -> #REF! | O36: =IF(#REF!>=80,"B","K") -> #REF! | Q36: =(#REF!/G36)*100 -> #REF! | R36: =#REF!/G36*100 -> #REF! | T36: =IF(Q36=#REF!,"BETUL","salah") -> #REF! | U36: =IF(#REF!=R36,"BETUL","SALAH") -> #REF! | V36: =IF(#REF!>80,"CEK KEMBALI","OKE") -> #REF! | W36: =IF(#REF!>80,"CEK KEMBALI","OKE") -> #REF!
A37: 24 | B37: =' TRAFO 80% no print '!B37 -> INDRAMAYU | C37: =' TRAFO 80% no print '!C37 -> IDMYU | D37: =' TRAFO 80% no print '!D37 -> 3 | E37: =' TRAFO 80% no print '!E37 -> 30 | F37: =' TRAFO 80% no print '!F37 -> 70/20 | G37: =' TRAFO 80% no print '!G37 -> 866 | H37: =' TRAFO 80% no print '!Z37 -> 697.98094 | I37: =' TRAFO 80% no print '!AA37 -> 80.598261 | J37: =' TRAFO 80% no print '!AD37 -> Malam | K37: =' TRAFO 80% no print '!L37 -> Wilayah Indramayu,Balongan | N37: =IF(#REF!>=80,"B","K") -> #REF! | O37: =IF(#REF!>=80,"B","K") -> #REF! | Q37: =(#REF!/G37)*100 -> #REF! | R37: =#REF!/G37*100 -> #REF! | T37: =IF(Q37=#REF!,"BETUL","salah") -> #REF! | U37: =IF(#REF!=R37,"BETUL","SALAH") -> #REF! | V37: =IF(#REF!>80,"CEK KEMBALI","OKE") -> #REF! | W37: =IF(#REF!>80,"CEK KEMBALI","OKE") -> #REF!
A38: 25 | B38: =' TRAFO 80% no print '!B38 -> INDRAMAYU | C38: =' TRAFO 80% no print '!C38 -> JTBRG | D38: =' TRAFO 80% no print '!D38 -> 3 | E38: =' TRAFO 80% no print '!E38 -> 60 | F38: =' TRAFO 80% no print '!F38 -> 150 /20 | G38: =' TRAFO 80% no print '!G38 -> 1732 | H38: =' TRAFO 80% no print '!Z38 -> 1652.5115 | I38: =' TRAFO 80% no print '!AA38 -> 95.410593 | J38: =' TRAFO 80% no print '!AD38 -> Malam | K38: =' TRAFO 80% no print '!L38 -> Wilayah Jatibarang | N38: =IF(#REF!>=80,"B","K") -> #REF! | O38: =IF(#REF!>=80,"B","K") -> #REF! | Q38: =(#REF!/G38)*100 -> #REF! | R38: =#REF!/G38*100 -> #REF! | T38: =IF(Q38=#REF!,"BETUL","salah") -> #REF! | U38: =IF(#REF!=R38,"BETUL","SALAH") -> #REF! | V38: =IF(#REF!>80,"CEK KEMBALI","OKE") -> #REF! | W38: =IF(#REF!>80,"CEK KEMBALI","OKE") -> #REF!
A39: 26 | B39: =' TRAFO 80% no print '!B39 -> CIREBON | C39: =' TRAFO 80% no print '!C39 -> KUNGN | D39: =' TRAFO 80% no print '!D39 -> 1 | E39: =' TRAFO 80% no print '!E39 -> 30 | F39: =' TRAFO 80% no print '!F39 -> 70/20 | G39: =' TRAFO 80% no print '!G39 -> 866 | H39: =' TRAFO 80% no print '!Z39 -> 725.6355 | I39: =' TRAFO 80% no print '!AA39 -> 83.791628 | J39: =' TRAFO 80% no print '!AD39 -> Siang | K39: =' TRAFO 80% no print '!L39 -> Wilayah umum Kuningan | N39: =IF(#REF!>=80,"B","K") -> #REF! | O39: =IF(#REF!>=80,"B","K") -> #REF! | Q39: =(#REF!/G39)*100 -> #REF! | R39: =#REF!/G39*100 -> #REF! | T39: =IF(Q39=#REF!,"BETUL","salah") -> #REF! | U39: =IF(#REF!=R39,"BETUL","SALAH") -> #REF! | V39: =IF(#REF!>80,"CEK KEMBALI","OKE") -> #REF! | W39: =IF(#REF!>80,"CEK KEMBALI","OKE") -> #REF!
... A56: 43 | B56: =' TRAFO 80% no print '!B56 -> TASIKMALAYA | C56: =' TRAFO 80% no print '!C56 -> TSBRU | D56: =' TRAFO 80% no print '!D56 -> 1 | E56: =' TRAFO 80% no print '!E56 -> 30 | F56: =' TRAFO 80% no print '!F56 -> 150/20 | G56: =' TRAFO 80% no print '!G56 -> 866 | H56: =' TRAFO 80% no print '!Z56 -> 844.21712 | I56: =' TRAFO 80% no print '!AA56 -> 97.484656 | J56: =' TRAFO 80% no print '!AD56 -> Siang | K56: =' TRAFO 80% no print '!L56 -> Wilayah Umum Tasikmalaya | N56: =IF(#REF!>=80,"B","K") -> #REF! | O56: =IF(#REF!>=80,"B","K") -> #REF! | Q56: =(#REF!/G56)*100 -> #REF! | R56: =#REF!/G56*100 -> #REF! | T56: =IF(Q56=#REF!,"BETUL","salah") -> #REF! | U56: =IF(#REF!=R56,"BETUL","SALAH") -> #REF! | V56: =IF(#REF!>80,"CEK KEMBALI","OKE") -> #REF! | W56: =IF(#REF!>80,"CEK KEMBALI","OKE") -> #REF!

Sheet  TRAFO 30% PRINT
B2: BEBAN TRAFO GARDU INDUK DISTRIBUSI JABAR & BANTEN
A5: LAMPIRAN XI.1 a
A6: BEBAN TRAFO GARDU INDUK < 30% UNIT INDUK DISTRIBUSI JAWA BARAT
A7: APRIL 2022
A8: N0 | B8: UP3 | C8: GI | D8: TRF | E8: DAYA | F8: TGN | G8: I-NOM | H8: April | K8: KETERANGAN
H9: Beban | J9: Siang
F10: (kV) | H10: A | I10: % | J10: Malam
A11: 1 | B11: =' TRAFO 30% no print'!B14 -> BANDUNG | C11: =' TRAFO 30% no print'!C14 -> BRAGA | D11: =' TRAFO 30% no print'!D14 -> 2 | E11: =' TRAFO 30% no print'!E14 -> 60 | F11: =' TRAFO 30% no print'!F14 -> 150/20 | G11: =' TRAFO 30% no print'!G14 -> 1732 | H11: =' TRAFO 30% no print'!Z14 -> 507.56437 | I11: =' TRAFO 30% no print'!AA14 -> 29.305102 | J11: ='[132] TRAFO 30% no print'!AD14 -> Siang | N11: =IF(#REF!>=80,"B","K") -> #REF! | O11: =IF(#REF!>=80,"B","K") -> #REF! | Q11: =(#REF!/G11)*100 -> #REF! | R11: =#REF!/G11*100 -> #REF! | T11: =IF(Q11=#REF!,"BETUL","salah") -> #REF! | U11: #REF! | V11: =IF(#REF!>80,"CEK KEMBALI","OKE") -> #REF! | W11: =IF(#REF!>80,"CEK KEMBALI","OKE") -> #REF!
A12: 2 | B12: =' TRAFO 30% no print'!B15 -> BANDUNG | C12: =' TRAFO 30% no print'!C15 -> DGPKR | D12: =' TRAFO 30% no print'!D15 -> 1 | E12: =' TRAFO 30% no print'!E15 -> 60 | F12: =' TRAFO 30% no print'!F15 -> 150/20 | G12: =' TRAFO 30% no print'!G15 -> 1732 | H12: =' TRAFO 30% no print'!Z15 -> 440.67873 | I12: =' TRAFO 30% no print'!AA15 -> 25.443345 | J12: ='[132] TRAFO 30% no print'!AD15 -> Siang | N12: =IF(#REF!>=80,"B","K") -> #REF! | O12: =IF(#REF!>=80,"B","K") -> #REF! | Q12: =(#REF!/G12)*100 -> #REF! | R12: =#REF!/G12*100 -> #REF! | T12: =IF(Q12=#REF!,"BETUL","salah") -> #REF! | U12: =IF(#REF!=R12,"BETUL","SALAH") -> #REF! | V12: =IF(#REF!>80,"CEK KEMBALI","OKE") -> #REF! | W12: =IF(#REF!>80,"CEK KEMBALI","OKE") -> #REF!
A13: 3 | B13: =' TRAFO 30% no print'!B16 -> BANDUNG | C13: =' TRAFO 30% no print'!C16 -> UBRNG | D13: =' TRAFO 30% no print'!D16 -> 6 | E13: =' TRAFO 30% no print'!E16 -> 60 | F13: =' TRAFO 30% no print'!F16 -> 150/20 | G13: =' TRAFO 30% no print'!G16 -> 1732 | H13: =' TRAFO 30% no print'!Z16 -> 458.69184 | I13: =' TRAFO 30% no print'!AA16 -> 26.483363 | J13: ='[132] TRAFO 30% no print'!AD16 -> Siang | N13: =IF(#REF!>=80,"B","K") -> #REF! | O13: =IF(#REF!>=80,"B","K") -> #REF! | Q13: =(#REF!/G13)*100 -> #REF! | R13: =#REF!/G13*100 -> #REF! | T13: #REF! | U13: =IF(#REF!=R13,"BETUL","SALAH") -> #REF! | V13: =IF(#REF!>80,"CEK KEMBALI","OKE") -> #REF! | W13: =IF(#REF!>80,"CEK KEMBALI","OKE") -> #REF!
